Workbook

Sheet Resumo
A1: Resumo — caixa necessário para o teste de anúncios
A2: Tudo calculado a partir da aba Premissas. Mude lá; esta aba recalcula.
A4: Indicador | B4: Valor | C4: Como ler
A5: Verba total de anúncios (sem imposto, como no Ads Manager) | B5: ='Fluxo diário'!C95 -> 700 | C5: fase 1 + fase 2
A6: Pedidos criados no período | B6: ='Fluxo diário'!G95+'Fluxo diário'!H95 -> 46.666667 | C6: leads × conversão
A7: dos quais COD / antecipado | B7: =TEXT('Fluxo diário'!G95,"0.0")&" / "&TEXT('Fluxo diário'!H95,"0.0") -> 32.7 / 14.0
A8: Faturamento bruto dos pedidos criados | B8: ='Fluxo diário'!G95*Premissas!$B$51+'Fluxo diário'!H95*Premissas!$B$52 -> 5880.14 | C8: antes de recusa/devolução
A9: PICO DE CAIXA NECESSÁRIO (anúncio pago na fatura) | B9: =-'Fluxo diário'!B99 -> 570.7235 | C9: produto + taxas antes do repasse; anúncio, IA, fixos e saque só no vencimento da fatura
A10: dia em que o pico acontece | B10: ='Fluxo diário'!B100 -> 16 | C10: contado do 1º dia de anúncio
A11: dia em que o caixa volta a zero | B11: ='Fluxo diário'!B101 -> 20 | C11: break-even de caixa acumulado
A12: Pico se o anúncio fosse pago no dia do gasto | B12: =-'Fluxo diário'!B102 -> 1367.5335 | C12: referência: sem o prazo da fatura
A13: Caixa disponível − margem de segurança | B13: =Premissas!$B$65-Premissas!$B$66 -> 1075 | C13: o que você pode usar de fato
A14: SOBRA / (FALTA) DE CAIXA | B14: =B13-B9 -> 504.2765 | C14: positivo = o caixa cobre o pico
A15: Caixa acumulado no dia 90 | B15: ='Fluxo diário'!S94 -> 1374.7394 | C15: lucro de caixa realizado (parte ainda a receber)
A16: Lucro esperado por venda (mix 70/30) | B16: =Unitário!B18 -> 31.922558 | C16: em regime, depois de recusa/devolução/lead/IA
A17: Escala máxima do teste com este caixa | B17: =IFERROR(B13/B9,0) -> 1.8835741 | C17: múltiplo da verba, mesmo perfil
A18: Fatura da Meta com o imposto repassado | B18: =B5*(1+Premissas!$B$17) -> 796.81 | C18: o que o cartão realmente cobra pela verba
A19: Leads no teste | B19: =B5/Premissas!$B$18 -> 466.66667 | C19: verba ÷ CPL
A20: Piso de amostra (mais de 500 leads e 50 pedidos) | B20: =IF(AND(B19>500,B6>50),"passa","abaixo do piso") -> abaixo do piso | C20: L3 item 4, assinado em 02/10
A22: Gasto antecipado e tempo até virar caixa — por caminho
A23: Por pedido criado (R$) | B23: Pagamento na entrega (COD) | C23: Pagamento antecipado | D23: Como ler
A24: Anúncio + IA + WhatsApp até o pedido | B24: =(Premissas!$B$18*(1+Premissas!$B$17)+Premissas!$B$20)/Premissas!$B$19+Premissas!$B$21 -> 19.8145 | C24: =(Premissas!$B$18*(1+Premissas!$B$17)+Premissas!$B$20)/Premissas!$B$19+Premissas!$B$21 -> 19.8145 | D24: o anúncio só sai do caixa no vencimento da fatura; IA/WhatsApp no dia 1
A25: Produto adiantado | B25: =Premissas!$B$59*Unitário!$B$22 -> 30 | C25: =Premissas!$B$59*Unitário!$B$22 -> 30 | D25: sai no dia do pedido
A26: Taxas adiantadas (logística + transação) | B26: =Premissas!$B$61*Unitário!$B$24+Premissas!$B$63*Unitário!$B$25 -> 32.716209 | C26: =Premissas!$B$31 -> 5 | D26: COD: logística + transação; antec.: manuseio (tudo do saldo de expedição)
A27: Estorno do que não foi entregue, já líquido da taxa de recusa/devolução | B27: =-Premissas!$B$26*(Premissas!$B$59*Unitário!$B$22+Premissas!$B$61*Unitário!$B$24+Premissas!$B$63*Unitário!$B$25)-(1-Premissas!$B$26)*Premissas!$B$27*(Premissas!$B$59*Unitário!$B$22+(1-Premissas!$B$62)*(Premissas!$B$61*Unitário!$B$24+Premissas!$B$63*Unitário!$B$25))+Premissas!$B$26*Premissas!$B$39+(1-Premissas!$B$26)*Premissas!$B$27*Premissas!$B$40 -> -11.678901 | C27: =-Premissas!$B$27*(Premissas!$B$59*Unitário!$B$22+(1-Premissas!$B$62)*Premissas!$B$31)+Premissas!$B$27*Premissas!$B$41 -> 1.5 | D27: volta no dia da tentativa / da devolução
A28: Total de caixa gasto antes do dinheiro entrar (sem anúncio) | B28: =SUM(B25:B27) -> 51.037308 | C28: =SUM(C25:C27) -> 36.5 | D28: produto + taxas, líquido de estornos
A29: Dias do pedido até o dinheiro estar disponível | B29: =Premissas!$B$54+Premissas!$B$55 -> 16 | C29: =Premissas!$B$56 -> 0 | D29: tempo em que o faturamento vira caixa
A30: Dinheiro que entra por pedido (líquido de recusa/devolução) | B30: =Unitário!$B$21*Premissas!$B$51 -> 97.0353 | C30: =(1-Premissas!$B$27)*Premissas!$B$52 -> 105.219 | D30: preço bruto recebido
A33: Sensibilidade — e se o teste escalar? (mesmo perfil de dias, verba multiplicada)
A34: Multiplicador da verba | B34: Verba total | C34: Pico de caixa necessário | D34: Falta / sobra com seu caixa
A35: 1 | B35: =A35*B5 -> 700 | C35: =A35*B9 -> 570.7235 | D35: =$B$13-C35 -> 504.2765
A36: 2 | B36: =A36*B5 -> 1400 | C36: =A36*B9 -> 1141.447 | D36: =$B$13-C36 -> -66.446997
A37: 3 | B37: =A37*B5 -> 2100 | C37: =A37*B9 -> 1712.1705 | D37: =$B$13-C37 -> -637.1705
A38: 5 | B38: =A38*B5 -> 3500 | C38: =A38*B9 -> 2853.6175 | D38: =$B$13-C38 -> -1778.6175
A39: 10 | B39: =A39*B5 -> 7000 | C39: =A39*B9 -> 5707.235 | D39: =$B$13-C39 -> -4632.235
A41: Aproximação linear: custos fixos (R$ 53,50/mês) não escalam e o dia do vencimento da fatura pode mudar com datas diferentes.

Sheet Premissas
A1: Premissas — modelo de caixa x verba de anúncios
A2: Azul = você edita. Amarelo = valor ASSUMIDO por mim, sem confirmação do operador (ver aba Perguntas). Preto = fórmula.
A4: Item | B4: Valor | C4: Unidade | D4: Origem / observação
A5: Anúncios — plano do teste (operador, 09/10)
A6: Fase 1 — verba total | B6: 350 | C6: R$ | D6: Operador, 09/10: 7 dias a R$ 50/dia (antes R$ 55/dia; antes ainda R$ 375 em 5 dias)
A7: Fase 1 — dias | B7: 7 | C7: dias | D7: Operador, 09/10: 7 dias (eram 5)
A8: Pausa entre as fases | B8: 2 | C8: dias | D8: Operador: 2 dias de respiro
A9: Fase 2 — verba total | B9: 350 | C9: R$ | D9: Operador, 09/10: 7 dias a R$ 50/dia (antes R$ 55/dia; antes ainda R$ 300 em 5 dias)
A10: Fase 2 — dias | B10: 7 | C10: dias | D10: Operador, 09/10: 7 dias (eram 5)
A11: Data do 1º dia de anúncio | B11: 46318 | C11: data | D11: Operador, 09/10: usar 23/10 para modelar (sexta-feira)
A12: Fatura do cartão: dia de fechamento | B12: 22 | C12: dia do mês | D12: Operador, 09/10 (gasto até o dia 22 entra na fatura do mês — confirmar se o dia 22 conta)
A13: Meta: limite de cobrança no cartão (ou fim do mês) | B13: 100 | C13: R$ | D13: Operador, 09/10: o Ads cobra ao bater R$ 100 ou no fim do mês; limite do cartão R$ 4.000
A14: Meta API (IA): limite de cobrança no cartão (ou fim do mês) | B14: 20 | C14: R$ | D14: Operador, 09/10: a API da Meta cobra ao chegar em R$ 20
A15: Saque do saldo até a conta: dias | B15: 2 | C15: dias | D15: Operador: D+1 a D+2 (usei 2); o saque sai antes do vencimento
A16: Fatura do cartão: dia de vencimento | B16: 29 | C16: dia do mês | D16: Operador, 09/10
A17: Imposto que a Meta soma à fatura no Brasil (PIS/Cofins + ISS) | B17: 0.1383 | C17: % sobre a verba | D17: Comunicado Meta: R$ 100 → R$ 113,83 no cartão. Operador, 09/10: 'deve aparecer' — conferir na 1ª fatura
... A21: WhatsApp (template pós-venda) por pedido | B21: 0.04 | C21: R$ | D21: Tabela Meta (~US$ 0,0068)
A22: Mix de vendas
A23: % dos pedidos em pagamento na entrega (COD) | B23: 0.7 | C23: % | D23: Operador (70/30)
A24: % dos pedidos em pagamento antecipado | B24: =1-Premissas!$B$23 -> 0.3 | C24: %
A25: Resultado do pedido
A26: Recusa na porta (só COD) | B26: 0.17 | C26: % | D26: Operador: faixa 12–17%, AINDA NÃO MEDIDA (ponta pessimista)
A27: Devolução depois de entregue (COD e antecipado) — % dos entregues | B27: 0.1 | C27: % | D27: Operador: faixa 5–10% (ponta pessimista). R27, 17/10 (operador): sobre os pedidos entregues
A28: Custos por pedido (docs 06-modelo-economico, 02/10)
A29: Produto, por peça | B29: 30 | C29: R$/peça | D29: Operador
A30: Taxa de entrega concluída (só COD) | B30: 19.99 | C30: R$/pedido | D30: Logzz
A31: Manuseio | B31: 5 | C31: R$/pedido | D31: Central Logzz R$ 5,00 (docs do projeto usavam R$ 4,99) — operador, 09/10
A32: Transação COD — % da comissão (preço − produto − entrega − manuseio) | B32: 0.0699 | C32: % | D32: Logzz, 'Taxas, prazos e condições': 6,99% sobre a comissão — R27, 17/10 (operador); antes aplicado ao preço cheio
A33: Transação COD — fixo | B33: 2.49 | C33: R$/pedido | D33: Logzz/Coinzz
A34: Mercado Pago Pix — % | B34: 0.0099 | C34: % | D34: Operador, 25/09
A35: Mercado Pago Pix — fixo | B35: 1 | C35: R$ | D35: Operador, 25/09
A36: Mercado Pago cartão à vista — % | B36: 0.0498 | C36: % | D36: Operador, 25/09
A37: % do antecipado pago em Pix (resto cartão) | B37: 0.5 | C37: % | D37: Premissa P2 do doc
A38: Entrega frustrada (recusa na porta) | B38: 4.99 | C38: R$/pedido | D38: Central Logzz; operador confirma, 09/10
A39: Custo TOTAL da recusa (frustrada + manuseio) | B39: =Premissas!$B$38+Premissas!$B$31 -> 9.99 | C39: R$/pedido | D39: Operador, 09/10: R$ 4,99 + R$ 5,00 = R$ 9,99. Só isso fica com você; o resto da logística volta
A40: Custo total da devolução — COD (valor fechado) | B40: 30 | C40: R$/pedido | D40: R27, 17/10 (operador): frete de volta, manuseio e taxas, tudo junto. Antes: R$ 45 de frete + manuseio + taxas que não voltavam = R$ 86,56
A41: Custo total da devolução — antecipado (valor fechado) | B41: 50 | C41: R$/pedido | D41: R27, 17/10 (operador): já com a taxa do Mercado Pago que não volta. Antes: R$ 58,99
A42: Impostos sobre faturamento recebido | B42: 0 | C42: % | D42: Operador: Simples, mas fora desta simulação por ora
A43: Custos fixos por mês (PikaPods R$ 18,50 + número WhatsApp R$ 35) | B43: 53.5 | C43: R$/mês | D43: Operador, 09/10: cobrados no cartão no dia 1; saem do caixa no vencimento da fatura
A44: Kits (peças por pedido)
...

Sheet Unitário
A1: Economia por pedido (R27, 17/10: transação de 6,99% sobre a comissão; devolução de R$ 30 / R$ 50 fechados, sobre os entregues)
A3: Linha (R$ por pedido criado) | B3: COD | C3: Antecipado | D3: Obs.
A4: Faturamento (preço médio) | B4: =Premissas!$B$51 -> 129.9 | C4: =Premissas!$B$52 -> 116.91
A5: Produto | B5: =-Premissas!$B$29*Premissas!$B$50 -> -30 | C5: =-Premissas!$B$29*Premissas!$B$50 -> -30 | D5: por peça
A6: Transação / taxa Mercado Pago | B6: =-(Premissas!$B$32*(Premissas!$B$51-Premissas!$B$29*Premissas!$B$50-Premissas!$B$30-Premissas!$B$31)+Premissas!$B$33) -> -7.726209 | C6: =-(Premissas!$B$37*(Premissas!$B$34*Premissas!$B$52+Premissas!$B$35)+(1-Premissas!$B$37)*Premissas!$B$36*Premissas!$B$52) -> -3.9897635
A7: Entrega concluída | B7: =-Premissas!$B$30 -> -19.99 | C7: =0 -> 0 | D7: só COD
A8: Manuseio | B8: =-Premissas!$B$31 -> -5 | C8: =-Premissas!$B$31 -> -5
A9: Margem se entregue | B9: =SUM(B4:B8) -> 67.183791 | C9: =SUM(C4:C8) -> 77.920237
A10: Perda esperada por recusa | B10: =-Premissas!$B$26*(B9+Premissas!$B$39) -> -13.119544 | C10: =0 -> 0 | D10: recusa × (margem + taxa)
A11: Perda esperada por devolução | B11: =-(1-Premissas!$B$26)*Premissas!$B$27*(B9+Premissas!$B$40) -> -8.0662547 | C11: =-Premissas!$B$27*(C9+Premissas!$B$41) -> -12.792024 | D11: devolução: perde a margem e paga o valor fechado (R27); só sobre o que foi entregue
A12: Margem esperada (antes de lead/IA/WhatsApp) | B12: =SUM(B9:B11) -> 45.997992 | C12: =SUM(C9:C11) -> 65.128213
A13: Lead (CPL ÷ conversão, com imposto da Meta) | B13: =-Premissas!$B$18*(1+Premissas!$B$17)/Premissas!$B$19 -> -17.0745 | C13: =-Premissas!$B$18*(1+Premissas!$B$17)/Premissas!$B$19 -> -17.0745 | D13: R$ 1,50 + 13,83% de imposto
A14: IA (custo por lead ÷ conversão) | B14: =-Premissas!$B$20/Premissas!$B$19 -> -2.7 | C14: =-Premissas!$B$20/Premissas!$B$19 -> -2.7
A15: WhatsApp | B15: =-Premissas!$B$21 -> -0.04 | C15: =-Premissas!$B$21 -> -0.04
A16: Impostos sobre o faturamento entregue | B16: =-Premissas!$B$42*Premissas!$B$51*(1-Premissas!$B$26-Premissas!$B$27) -> 0 | C16: =-Premissas!$B$42*Premissas!$B$52*(1-Premissas!$B$27) -> 0
A17: LUCRO POR VENDA | B17: =SUM(B12:B16) -> 26.183492 | C17: =SUM(C12:C16) -> 45.313713
A18: Lucro por venda — mix COD/antecipado | B18: =Premissas!$B$23*B17+Premissas!$B$24*C17 -> 31.922558
A20: Parâmetros usados no fluxo diário
A21: COD: fração entregue e mantida ((1 − recusa) × (1 − devolução)) | B21: =(1-Premissas!$B$26)*(1-Premissas!$B$27) -> 0.747
A22: Produto por pedido (R$) | B22: =Premissas!$B$29*Premissas!$B$50 -> 30
A23: COD: taxas por pedido ENTREGUE (transação+entrega+manuseio) | B23: =-(B6+B7+B8) -> 32.716209
A24: COD: logística por pedido (entrega concluída + manuseio) | B24: =-(B7+B8) -> 24.99
A25: COD: transação por pedido (6,99% da comissão + R$ 2,49) | B25: =-B6 -> 7.726209
A26: COD: taxas esperadas por pedido criado (entregue + recusa + devolução) | B26: =Unitário!$B$21*Unitário!$B$23+Premissas!$B$26*Premissas!$B$39+(1-Premissas!$B$26)*Premissas!$B$27*Premissas!$B$40 -> 28.627308
A27: Antecipado: taxa Mercado Pago por pedido | B27: =-C6 -> 3.9897635

Sheet Fluxo diário
A1: Fluxo de caixa diário (R$) — entradas positivas, saídas negativas
A2: Cada dia de verba gera pedidos; cada pedido gera saídas e entradas deslocadas pelos prazos da aba Premissas. O anúncio sai do caixa só no vencimento da fatura.
A4: Dia | B4: Data | C4: Gasto de anúncio incorrido (cartão) | D4: Dia do vencimento da fatura | E4: Anúncios (saída de caixa) | F4: IA + WhatsApp | G4: Pedidos COD criados | H4: Pedidos antec. criados | I4: COD: produto + taxas (saldo de expedição) | J4: COD: recusa (estorno − taxa) | K4: COD: devolução (estorno − custos) | L4: COD: repasse (entrada) | M4: Antec.: entrada MP | N4: Antec.: produto + manuseio (saldo de expedição) | O4: Antec.: devolução | P4: Impostos | Q4: Custos fixos | R4: Líquido do dia | S4: Caixa acumulado | T4: Marcador | U4: Caixa acumulado se o anúncio fosse pago no dia | V4: WhatsApp incorrido | W4: Dia do caixa do WhatsApp (cobrado dia 1 no cartão) | X4: Saldo a cobrar da Meta (verba + imposto) | Y4: Cobrança da Meta no cartão | Z4: Saldo a cobrar da API de IA | AA4: Cobrança da API de IA no cartão | AB4: Dia do caixa da cobrança de IA
A5: 1 | B5: =Premissas!$B$11+A5-1 -> 46318 | C5: =IF(A5<=Premissas!$B$7,Premissas!$B$6/Premissas!$B$7,IF(A5<=Premissas!$B$7+Premissas!$B$8,0,IF(A5<=Premissas!$B$7+Premissas!$B$8+Premissas!$B$10,Premissas!$B$9/Premissas!$B$10,0))) -> 50 | D5: =IF(Y5>0,IF(DAY(B5)<=Premissas!$B$12,DATE(YEAR(B5),MONTH(B5),Premissas!$B$16),DATE(YEAR(B5),MONTH(B5)+1,Premissas!$B$16))-Premissas!$B$11+1-Premissas!$B$15,0) -> 0 | E5: =-SUMIF($D$5:$D$94,A5,$Y$5:$Y$94) -> 0 | F5: =-SUMIF($W$5:$W$94,A5,$V$5:$V$94)-SUMIF($AB$5:$AB$94,A5,$AA$5:$AA$94) -> 0 | G5: =C5/Premissas!$B$18*Premissas!$B$19*Premissas!$B$23 -> 2.3333333 | H5: =C5/Premissas!$B$18*Premissas!$B$19*Premissas!$B$24 -> 1 | I5: =-IF($A5-(Premissas!$B$60)>=1,INDEX($G$5:$G$94,$A5-(Premissas!$B$60)),0)*(Premissas!$B$59*Unitário!$B$22+(Premissas!$B$61*Unitário!$B$24+Premissas!$B$63*Unitário!$B$25)) -> 0 | J5: =IF($A5-(Premissas!$B$54)>=1,INDEX($G$5:$G$94,$A5-(Premissas!$B$54)),0)*Premissas!$B$26*((Premissas!$B$59*Unitário!$B$22+(Premissas!$B$61*Unitário!$B$24+Premissas!$B$63*Unitário!$B$25))-Premissas!$B$39) -> 0 | K5: =IF($A5-(Premissas!$B$54+Premissas!$B$57)>=1,INDEX($G$5:$G$94,$A5-(Premissas!$B$54+Premissas!$B$57)),0)*(1-Premissas!$B$26)*Premissas!$B$27*(Premissas!$B$59*Unitário!$B$22+(1-Premissas!$B$62)*(Premissas!$B$61*Unitário!$B$24+Premissas!$B$63*Unitário!$B$25)-Premissas!$B$62*((1-Premissas!$B$61)*Unitário!$B$24+(1-Premissas!$B$63)*Unitário!$B$25)-Premissas!$B$40) -> 0 | L5: =IF($A5-(Premissas!$B$54+Premissas!$B$55)>=1,INDEX($G$5:$G$94,$A5-(Premissas!$B$54+Premissas!$B$55)),0)*Unitário!$B$21*(Premissas!$B$51-(1-Premissas!$B$61)*Unitário!$B$24-(1-Premissas!$B$63)*Unitário!$B$25-(1-Premissas!$B$59)*Unitário!$B$22) -> 0 | M5: =IF($A5-(Premissas!$B$56)>=1,INDEX($H$5:$H$94,$A5-(Premissas!$B$56)),0)*(Premissas!$B$52-Unitário!$B$27) -> 112.92024 | N5: =-IF($A5-(Premissas!$B$60)>=1,INDEX($H$5:$H$94,$A5-(Premissas!$B$60)),0)*(Premissas!$B$59*Unitário!$B$22+Premissas!$B$31) -> 0 | O5: =IF($A5-(Premissas!$B$54+Premissas!$B$57)>=1,INDEX($H$5:$H$94,$A5-(Premissas!$B$54+Premissas!$B$57)),0)*Premissas!$B$27*(-Premissas!$B$52-Premissas!$B$41+Unitário!$B$27+(1-Premissas!$B$62)*Premissas!$B$31+Premissas!$B$59*Unitário!$B$22) -> 0 | P5: =-Premissas!$B$42*(IF($A5-(Premissas!$B$54+Premissas!$B$55)>=1,INDEX($G$5:$G$94,$A5-(Premissas!$B$54+Premissas!$B$55)),0)*Unitário!$B$21*Premissas!$B$51+IF($A5-(Premissas!$B$56)>=1,INDEX($H$5:$H$94,$A5-(Premissas!$B$56)),0)*(1-Premissas!$B$27)*Premissas!$B$52) -> 0 | Q5: =-IF(AND(DAY(B5+Premissas!$B$15)=Premissas!$B$16,B5+Premissas!$B$15>=DATE(YEAR(Premissas!$B$11),MONTH(Premissas!$B$11)+1,Premissas!$B$16)),Premissas!$B$43,0)-IF(OR(E5<0,F5<0,IF(AND(DAY(B5+Premissas!$B$15)=Premissas!$B$16,B5+Premissas!$B$15>=DATE(YEAR(Premissas!$B$11),MONTH(Premissas!$B$11)+1,Premissas!$B$16)),Premissas!$B$43,0)>0),Premissas!$B$67*Premissas!$B$68,0) -> 0 | R5: =E5+F5+SUM(I5:Q5) -> 112.92024 | S5: =R5 -> 112.92024 | T5: =IF(AND($A5>$B$100,S5>=0),1,0) -> 0 | U5: =S5-SUM($E$5:E5)-(1+Premissas!$B$17)*SUM($C$5:C5) -> 56.005237 | V5: =(G5+H5)*Premissas!$B$21 -> 0.13333333 | W5: =IF(V5>0,DATE(YEAR(B5),MONTH(B5)+1,Premissas!$B$16)-Premissas!$B$11+1-Premissas!$B$15,0) -> 36 | X5: =C5*(1+Premissas!$B$17) -> 56.915 | Y5: =IF(OR(X5>=Premissas!$B$13,B5=DATE(YEAR(B5),MONTH(B5)+1,0)),X5,0) -> 0 | Z5: =C5/Premissas!$B$18*Premissas!$B$20 -> 9 | AA5: =IF(OR(Z5>=Premissas!$B$14,B5=DATE(YEAR(B5),MONTH(B5)+1,0)),Z5,0) -> 0 | AB5: =IF(AA5>0,IF(DAY(B5)<=Premissas!$B$12,DATE(YEAR(B5),MONTH(B5),Premissas!$B$16),DATE(YEAR(B5),MONTH(B5)+1,Premissas!$B$16))-Premissas!$B$11+1-Premissas!$B$15,0) -> 0
A6: 2 | B6: =Premissas!$B$11+A6-1 -> 46319 | C6: =IF(A6<=Premissas!$B$7,Premissas!$B$6/Premissas!$B$7,IF(A6<=Premissas!$B$7+Premissas!$B$8,0,IF(A6<=Premissas!$B$7+Premissas!$B$8+Premissas!$B$10,Premissas!$B$9/Premissas!$B$10,0))) -> 50 | D6: =IF(Y6>0,IF(DAY(B6)<=Premissas!$B$12,DATE(YEAR(B6),MONTH(B6),Premissas!$B$16),DATE(YEAR(B6),MONTH(B6)+1,Premissas!$B$16))-Premissas!$B$11+1-Premissas!$B$15,0) -> 36 | E6: =-SUMIF($D$5:$D$94,A6,$Y$5:$Y$94) -> 0 | F6: =-SUMIF($W$5:$W$94,A6,$V$5:$V$94)-SUMIF($AB$5:$AB$94,A6,$AA$5:$AA$94) -> 0 | G6: =C6/Premissas!$B$18*Premissas!$B$19*Premissas!$B$23 -> 2.3333333 | H6: =C6/Premissas!$B$18*Premissas!$B$19*Premissas!$B$24 -> 1 | I6: =-IF($A6-(Premissas!$B$60)>=1,INDEX($G$5:$G$94,$A6-(Premissas!$B$60)),0)*(Premissas!$B$59*Unitário!$B$22+(Premissas!$B$61*Unitário!$B$24+Premissas!$B$63*Unitário!$B$25)) -> -146.33782 | J6: =IF($A6-(Premissas!$B$54)>=1,INDEX($G$5:$G$94,$A6-(Premissas!$B$54)),0)*Premissas!$B$26*((Premissas!$B$59*Unitário!$B$22+(Premissas!$B$61*Unitário!$B$24+Premissas!$B$63*Unitário!$B$25))-Premissas!$B$39) -> 0 | K6: =IF($A6-(Premissas!$B$54+Premissas!$B$57)>=1,INDEX($G$5:$G$94,$A6-(Premissas!$B$54+Premissas!$B$57)),0)*(1-Premissas!$B$26)*Premissas!$B$27*(Premissas!$B$59*Unitário!$B$22+(1-Premissas!$B$62)*(Premissas!$B$61*Unitário!$B$24+Premissas!$B$63*Unitário!$B$25)-Premissas!$B$62*((1-Premissas!$B$61)*Unitário!$B$24+(1-Premissas!$B$63)*Unitário!$B$25)-Premissas!$B$40) -> 0 | L6: =IF($A6-(Premissas!$B$54+Premissas!$B$55)>=1,INDEX($G$5:$G$94,$A6-(Premissas!$B$54+Premissas!$B$55)),0)*Unitário!$B$21*(Premissas!$B$51-(1-Premissas!$B$61)*Unitário!$B$24-(1-Premissas!$B$63)*Unitário!$B$25-(1-Premissas!$B$59)*Unitário!$B$22) -> 0 | M6: =IF($A6-(Premissas!$B$56)>=1,INDEX($H$5:$H$94,$A6-(Premissas!$B$56)),0)*(Premissas!$B$52-Unitário!$B$27) -> 112.92024 | N6: =-IF($A6-(Premissas!$B$60)>=1,INDEX($H$5:$H$94,$A6-(Premissas!$B$60)),0)*(Premissas!$B$59*Unitário!$B$22+Premissas!$B$31) -> -35 | O6: =IF($A6-(Premissas!$B$54+Premissas!$B$57)>=1,INDEX($H$5:$H$94,$A6-(Premissas!$B$54+Premissas!$B$57)),0)*Premissas!$B$27*(-Premissas!$B$52-Premissas!$B$41+Unitário!$B$27+(1-Premissas!$B$62)*Premissas!$B$31+Premissas!$B$59*Unitário!$B$22) -> 0 | P6: =-Premissas!$B$42*(IF($A6-(Premissas!$B$54+Premissas!$B$55)>=1,INDEX($G$5:$G$94,$A6-(Premissas!$B$54+Premissas!$B$55)),0)*Unitário!$B$21*Premissas!$B$51+IF($A6-(Premissas!$B$56)>=1,INDEX($H$5:$H$94,$A6-(Premissas!$B$56)),0)*(1-Premissas!$B$27)*Premissas!$B$52) -> 0 | Q6: =-IF(AND(DAY(B6+Premissas!$B$15)=Premissas!$B$16,B6+Premissas!$B$15>=DATE(YEAR(Premissas!$B$11),MONTH(Premissas!$B$11)+1,Premissas!$B$16)),Premissas!$B$43,0)-IF(OR(E6<0,F6<0,IF(AND(DAY(B6+Premissas!$B$15)=Premissas!$B$16,B6+Premissas!$B$15>=DATE(YEAR(Premissas!$B$11),MONTH(Premissas!$B$11)+1,Premissas!$B$16)),Premissas!$B$43,0)>0),Premissas!$B$67*Premissas!$B$68,0) -> 0 | R6: =E6+F6+SUM(I6:Q6) -> -68.417585 | S6: =S5+R6 -> 44.502652 | T6: =IF(AND($A6>$B$100,S6>=0),1,0) -> 0 | U6: =S6-SUM($E$5:E6)-(1+Premissas!$B$17)*SUM($C$5:C6) -> -69.327348 | V6: =(G6+H6)*Premissas!$B$21 -> 0.13333333 | W6: =IF(V6>0,DATE(YEAR(B6),MONTH(B6)+1,Premissas!$B$16)-Premissas!$B$11+1-Premissas!$B$15,0) -> 36 | X6: =X5-Y5+C6*(1+Premissas!$B$17) -> 113.83 | Y6: =IF(OR(X6>=Premissas!$B$13,B6=DATE(YEAR(B6),MONTH(B6)+1,0)),X6,0) -> 113.83 | Z6: =Z5-AA5+C6/Premissas!$B$18*Premissas!$B$20 -> 18 | AA6: =IF(OR(Z6>=Premissas!$B$14,B6=DATE(YEAR(B6),MONTH(B6)+1,0)),Z6,0) -> 0 | AB6: =IF(AA6>0,IF(DAY(B6)<=Premissas!$B$12,DATE(YEAR(B6),MONTH(B6),Premissas!$B$16),DATE(YEAR(B6),MONTH(B6)+1,Premissas!$B$16))-Premissas!$B$11+1-Premissas!$B$15,0) -> 0
A7: 3 | B7: =Premissas!$B$11+A7-1 -> 46320 | C7: =IF(A7<=Premissas!$B$7,Premissas!$B$6/Premissas!$B$7,IF(A7<=Premissas!$B$7+Premissas!$B$8,0,IF(A7<=Premissas!$B$7+Premissas!$B$8+Premissas!$B$10,Premissas!$B$9/Premissas!$B$10,0))) -> 50 | D7: =IF(Y7>0,IF(DAY(B7)<=Premissas!$B$12,DATE(YEAR(B7),MONTH(B7),Premissas!$B$16),DATE(YEAR(B7),MONTH(B7)+1,Premissas!$B$16))-Premissas!$B$11+1-Premissas!$B$15,0) -> 0 | E7: =-SUMIF($D$5:$D$94,A7,$Y$5:$Y$94) -> 0 | F7: =-SUMIF($W$5:$W$94,A7,$V$5:$V$94)-SUMIF($AB$5:$AB$94,A7,$AA$5:$AA$94) -> 0 | G7: =C7/Premissas!$B$18*Premissas!$B$19*Premissas!$B$23 -> 2.3333333 | H7: =C7/Premissas!$B$18*Premissas!$B$19*Premissas!$B$24 -> 1 | I7: =-IF($A7-(Premissas!$B$60)>=1,INDEX($G$5:$G$94,$A7-(Premissas!$B$60)),0)*(Premissas!$B$59*Unitário!$B$22+(Premissas!$B$61*Unitário!$B$24+Premissas!$B$63*Unitário!$B$25)) -> -146.33782 | J7: =IF($A7-(Premissas!$B$54)>=1,INDEX($G$5:$G$94,$A7-(Premissas!$B$54)),0)*Premissas!$B$26*((Premissas!$B$59*Unitário!$B$22+(Premissas!$B$61*Unitário!$B$24+Premissas!$B$63*Unitário!$B$25))-Premissas!$B$39) -> 20.91473 | K7: =IF($A7-(Premissas!$B$54+Premissas!$B$57)>=1,INDEX($G$5:$G$94,$A7-(Premissas!$B$54+Premissas!$B$57)),0)*(1-Premissas!$B$26)*Premissas!$B$27*(Premissas!$B$59*Unitário!$B$22+(1-Premissas!$B$62)*(Premissas!$B$61*Unitário!$B$24+Premissas!$B$63*Unitário!$B$25)-Premissas!$B$62*((1-Premissas!$B$61)*Unitário!$B$24+(1-Premissas!$B$63)*Unitário!$B$25)-Premissas!$B$40) -> 0 | L7: =IF($A7-(Premissas!$B$54+Premissas!$B$55)>=1,INDEX($G$5:$G$94,$A7-(Premissas!$B$54+Premissas!$B$55)),0)*Unitário!$B$21*(Premissas!$B$51-(1-Premissas!$B$61)*Unitário!$B$24-(1-Premissas!$B$63)*Unitário!$B$25-(1-Premissas!$B$59)*Unitário!$B$22) -> 0 | M7: =IF($A7-(Premissas!$B$56)>=1,INDEX($H$5:$H$94,$A7-(Premissas!$B$56)),0)*(Premissas!$B$52-Unitário!$B$27) -> 112.92024 | N7: =-IF($A7-(Premissas!$B$60)>=1,INDEX($H$5:$H$94,$A7-(Premissas!$B$60)),0)*(Premissas!$B$59*Unitário!$B$22+Premissas!$B$31) -> -35 | O7: =IF($A7-(Premissas!$B$54+Premissas!$B$57)>=1,INDEX($H$5:$H$94,$A7-(Premissas!$B$54+Premissas!$B$57)),0)*Premissas!$B$27*(-Premissas!$B$52-Premissas!$B$41+Unitário!$B$27+(1-Premissas!$B$62)*Premissas!$B$31+Premissas!$B$59*Unitário!$B$22) -> 0 | P7: =-Premissas!$B$42*(IF($A7-(Premissas!$B$54+Premissas!$B$55)>=1,INDEX($G$5:$G$94,$A7-(Premissas!$B$54+Premissas!$B$55)),0)*Unitário!$B$21*Premissas!$B$51+IF($A7-(Premissas!$B$56)>=1,INDEX($H$5:$H$94,$A7-(Premissas!$B$56)),0)*(1-Premissas!$B$27)*Premissas!$B$52) -> 0 | Q7: =-IF(AND(DAY(B7+Premissas!$B$15)=Premissas!$B$16,B7+Premissas!$B$15>=DATE(YEAR(Premissas!$B$11),MONTH(Premissas!$B$11)+1,Premissas!$B$16)),Premissas!$B$43,0)-IF(OR(E7<0,F7<0,IF(AND(DAY(B7+Premissas!$B$15)=Premissas!$B$16,B7+Premissas!$B$15>=DATE(YEAR(Premissas!$B$11),MONTH(Premissas!$B$11)+1,Premissas!$B$16)),Premissas!$B$43,0)>0),Premissas!$B$67*Premissas!$B$68,0) -> 0 | R7: =E7+F7+SUM(I7:Q7) -> -47.502855 | S7: =S6+R7 -> -3.0002029 | T7: =IF(AND($A7>$B$100,S7>=0),1,0) -> 0 | U7: =S7-SUM($E$5:E7)-(1+Premissas!$B$17)*SUM($C$5:C7) -> -173.7452 | V7: =(G7+H7)*Premissas!$B$21 -> 0.13333333 | W7: =IF(V7>0,DATE(YEAR(B7),MONTH(B7)+1,Premissas!$B$16)-Premissas!$B$11+1-Premissas!$B$15,0) -> 36 | X7: =X6-Y6+C7*(1+Premissas!$B$17) -> 56.915 | Y7: =IF(OR(X7>=Premissas!$B$13,B7=DATE(YEAR(B7),MONTH(B7)+1,0)),X7,0) -> 0 | Z7: =Z6-AA6+C7/Premissas!$B$18*Premissas!$B$20 -> 27 | AA7: =IF(OR(Z7>=Premissas!$B$14,B7=DATE(YEAR(B7),MONTH(B7)+1,0)),Z7,0) -> 27 | AB7: =IF(AA7>0,IF(DAY(B7)<=Premissas!$B$12,DATE(YEAR(B7),MONTH(B7),Premissas!$B$16),DATE(YEAR(B7),MONTH(B7)+1,Premissas!$B$16))-Premissas!$B$11+1-Premissas!$B$15,0) -> 36
A8: 4 | B8: =Premissas!$B$11+A8-1 -> 46321 | C8: =IF(A8<=Premissas!$B$7,Premissas!$B$6/Premissas!$B$7,IF(A8<=Premissas!$B$7+Premissas!$B$8,0,IF(A8<=Premissas!$B$7+Premissas!$B$8+Premissas!$B$10,Premissas!$B$9/Premissas!$B$10,0))) -> 50 | D8: =IF(Y8>0,IF(DAY(B8)<=Premissas!$B$12,DATE(YEAR(B8),MONTH(B8),Premissas!$B$16),DATE(YEAR(B8),MONTH(B8)+1,Premissas!$B$16))-Premissas!$B$11+1-Premissas!$B$15,0) -> 36 | E8: =-SUMIF($D$5:$D$94,A8,$Y$5:$Y$94) -> 0 | F8: =-SUMIF($W$5:$W$94,A8,$V$5:$V$94)-SUMIF($AB$5:$AB$94,A8,$AA$5:$AA$94) -> 0 | G8: =C8/Premissas!$B$18*Premissas!$B$19*Premissas!$B$23 -> 2.3333333 | H8: =C8/Premissas!$B$18*Premissas!$B$19*Premissas!$B$24 -> 1 | I8: =-IF($A8-(Premissas!$B$60)>=1,INDEX($G$5:$G$94,$A8-(Premissas!$B$60)),0)*(Premissas!$B$59*Unitário!$B$22+(Premissas!$B$61*Unitário!$B$24+Premissas!$B$63*Unitário!$B$25)) -> -146.33782 | J8: =IF($A8-(Premissas!$B$54)>=1,INDEX($G$5:$G$94,$A8-(Premissas!$B$54)),0)*Premissas!$B$26*((Premissas!$B$59*Unitário!$B$22+(Premissas!$B$61*Unitário!$B$24+Premissas!$B$63*Unitário!$B$25))-Premissas!$B$39) -> 20.91473 | K8: =IF($A8-(Premissas!$B$54+Premissas!$B$57)>=1,INDEX($G$5:$G$94,$A8-(Premissas!$B$54+Premissas!$B$57)),0)*(1-Premissas!$B$26)*Premissas!$B$27*(Premissas!$B$59*Unitário!$B$22+(1-Premissas!$B$62)*(Premissas!$B$61*Unitário!$B$24+Premissas!$B$63*Unitário!$B$25)-Premissas!$B$62*((1-Premissas!$B$61)*Unitário!$B$24+(1-Premissas!$B$63)*Unitário!$B$25)-Premissas!$B$40) -> 0 | L8: =IF($A8-(Premissas!$B$54+Premissas!$B$55)>=1,INDEX($G$5:$G$94,$A8-(Premissas!$B$54+Premissas!$B$55)),0)*Unitário!$B$21*(Premissas!$B$51-(1-Premissas!$B$61)*Unitário!$B$24-(1-Premissas!$B$63)*Unitário!$B$25-(1-Premissas!$B$59)*Unitário!$B$22) -> 0 | M8: =IF($A8-(Premissas!$B$56)>=1,INDEX($H$5:$H$94,$A8-(Premissas!$B$56)),0)*(Premissas!$B$52-Unitário!$B$27) -> 112.92024 | N8: =-IF($A8-(Premissas!$B$60)>=1,INDEX($H$5:$H$94,$A8-(Premissas!$B$60)),0)*(Premissas!$B$59*Unitário!$B$22+Premissas!$B$31) -> -35 | O8: =IF($A8-(Premissas!$B$54+Premissas!$B$57)>=1,INDEX($H$5:$H$94,$A8-(Premissas!$B$54+Premissas!$B$57)),0)*Premissas!$B$27*(-Premissas!$B$52-Premissas!$B$41+Unitário!$B$27+(1-Premissas!$B$62)*Premissas!$B$31+Premissas!$B$59*Unitário!$B$22) -> 0 | P8: =-Premissas!$B$42*(IF($A8-(Premissas!$B$54+Premissas!$B$55)>=1,INDEX($G$5:$G$94,$A8-(Premissas!$B$54+Premissas!$B$55)),0)*Unitário!$B$21*Premissas!$B$51+IF($A8-(Premissas!$B$56)>=1,INDEX($H$5:$H$94,$A8-(Premissas!$B$56)),0)*(1-Premissas!$B$27)*Premissas!$B$52) -> 0 | Q8: =-IF(AND(DAY(B8+Premissas!$B$15)=Premissas!$B$16,B8+Premissas!$B$15>=DATE(YEAR(Premissas!$B$11),MONTH(Premissas!$B$11)+1,Premissas!$B$16)),Premissas!$B$43,0)-IF(OR(E8<0,F8<0,IF(AND(DAY(B8+Premissas!$B$15)=Premissas!$B$16,B8+Premissas!$B$15>=DATE(YEAR(Premissas!$B$11),MONTH(Premissas!$B$11)+1,Premissas!$B$16)),Premissas!$B$43,0)>0),Premissas!$B$67*Premissas!$B$68,0) -> 0 | R8: =E8+F8+SUM(I8:Q8) -> -47.502855 | S8: =S7+R8 -> -50.503058 | T8: =IF(AND($A8>$B$100,S8>=0),1,0) -> 0 | U8: =S8-SUM($E$5:E8)-(1+Premissas!$B$17)*SUM($C$5:C8) -> -278.16306 | V8: =(G8+H8)*Premissas!$B$21 -> 0.13333333 | W8: =IF(V8>0,DATE(YEAR(B8),MONTH(B8)+1,Premissas!$B$16)-Premissas!$B$11+1-Premissas!$B$15,0) -> 36 | X8: =X7-Y7+C8*(1+Premissas!$B$17) -> 113.83 | Y8: =IF(OR(X8>=Premissas!$B$13,B8=DATE(YEAR(B8),MONTH(B8)+1,0)),X8,0) -> 113.83 | Z8: =Z7-AA7+C8/Premissas!$B$18*Premissas!$B$20 -> 9 | AA8: =IF(OR(Z8>=Premissas!$B$14,B8=DATE(YEAR(B8),MONTH(B8)+1,0)),Z8,0) -> 0 | AB8: =IF(AA8>0,IF(DAY(B8)<=Premissas!$B$12,DATE(YEAR(B8),MONTH(B8),Premissas!$B$16),DATE(YEAR(B8),MONTH(B8)+1,Premissas!$B$16))-Premissas!$B$11+1-Premissas!$B$15,0) -> 0
A9: 5 | B9: =Premissas!$B$11+A9-1 -> 46322 | C9: =IF(A9<=Premissas!$B$7,Premissas!$B$6/Premissas!$B$7,IF(A9<=Premissas!$B$7+Premissas!$B$8,0,IF(A9<=Premissas!$B$7+Premissas!$B$8+Premissas!$B$10,Premissas!$B$9/Premissas!$B$10,0))) -> 50 | D9: =IF(Y9>0,IF(DAY(B9)<=Premissas!$B$12,DATE(YEAR(B9),MONTH(B9),Premissas!$B$16),DATE(YEAR(B9),MONTH(B9)+1,Premissas!$B$16))-Premissas!$B$11+1-Premissas!$B$15,0) -> 0 | E9: =-SUMIF($D$5:$D$94,A9,$Y$5:$Y$94) -> 0 | F9: =-SUMIF($W$5:$W$94,A9,$V$5:$V$94)-SUMIF($AB$5:$AB$94,A9,$AA$5:$AA$94) -> 0 | G9: =C9/Premissas!$B$18*Premissas!$B$19*Premissas!$B$23 -> 2.3333333 | H9: =C9/Premissas!$B$18*Premissas!$B$19*Premissas!$B$24 -> 1 | I9: =-IF($A9-(Premissas!$B$60)>=1,INDEX($G$5:$G$94,$A9-(Premissas!$B$60)),0)*(Premissas!$B$59*Unitário!$B$22+(Premissas!$B$61*Unitário!$B$24+Premissas!$B$63*Unitário!$B$25)) -> -146.33782 | J9: =IF($A9-(Premissas!$B$54)>=1,INDEX($G$5:$G$94,$A9-(Premissas!$B$54)),0)*Premissas!$B$26*((Premissas!$B$59*Unitário!$B$22+(Premissas!$B$61*Unitário!$B$24+Premissas!$B$63*Unitário!$B$25))-Premissas!$B$39) -> 20.91473 | K9: =IF($A9-(Premissas!$B$54+Premissas!$B$57)>=1,INDEX($G$5:$G$94,$A9-(Premissas!$B$54+Premissas!$B$57)),0)*(1-Premissas!$B$26)*Premissas!$B$27*(Premissas!$B$59*Unitário!$B$22+(1-Premissas!$B$62)*(Premissas!$B$61*Unitário!$B$24+Premissas!$B$63*Unitário!$B$25)-Premissas!$B$62*((1-Premissas!$B$61)*Unitário!$B$24+(1-Premissas!$B$63)*Unitário!$B$25)-Premissas!$B$40) -> 0 | L9: =IF($A9-(Premissas!$B$54+Premissas!$B$55)>=1,INDEX($G$5:$G$94,$A9-(Premissas!$B$54+Premissas!$B$55)),0)*Unitário!$B$21*(Premissas!$B$51-(1-Premissas!$B$61)*Unitário!$B$24-(1-Premissas!$B$63)*Unitário!$B$25-(1-Premissas!$B$59)*Unitário!$B$22) -> 0 | M9: =IF($A9-(Premissas!$B$56)>=1,INDEX($H$5:$H$94,$A9-(Premissas!$B$56)),0)*(Premissas!$B$52-Unitário!$B$27) -> 112.92024 | N9: =-IF($A9-(Premissas!$B$60)>=1,INDEX($H$5:$H$94,$A9-(Premissas!$B$60)),0)*(Premissas!$B$59*Unitário!$B$22+Premissas!$B$31) -> -35 | O9: =IF($A9-(Premissas!$B$54+Premissas!$B$57)>=1,INDEX($H$5:$H$94,$A9-(Premissas!$B$54+Premissas!$B$57)),0)*Premissas!$B$27*(-Premissas!$B$52-Premissas!$B$41+Unitário!$B$27+(1-Premissas!$B$62)*Premissas!$B$31+Premissas!$B$59*Unitário!$B$22) -> 0 | P9: =-Premissas!$B$42*(IF($A9-(Premissas!$B$54+Premissas!$B$55)>=1,INDEX($G$5:$G$94,$A9-(Premissas!$B$54+Premissas!$B$55)),0)*Unitário!$B$21*Premissas!$B$51+IF($A9-(Premissas!$B$56)>=1,INDEX($H$5:$H$94,$A9-(Premissas!$B$56)),0)*(1-Premissas!$B$27)*Premissas!$B$52) -> 0 | Q9: =-IF(AND(DAY(B9+Premissas!$B$15)=Premissas!$B$16,B9+Premissas!$B$15>=DATE(YEAR(Premissas!$B$11),MONTH(Premissas!$B$11)+1,Premissas!$B$16)),Premissas!$B$43,0)-IF(OR(E9<0,F9<0,IF(AND(DAY(B9+Premissas!$B$15)=Premissas!$B$16,B9+Premissas!$B$15>=DATE(YEAR(Premissas!$B$11),MONTH(Premissas!$B$11)+1,Premissas!$B$16)),Premissas!$B$43,0)>0),Premissas!$B$67*Premissas!$B$68,0) -> 0 | R9: =E9+F9+SUM(I9:Q9) -> -47.502855 | S9: =S8+R9 -> -98.005913 | T9: =IF(AND($A9>$B$100,S9>=0),1,0) -> 0 | U9: =S9-SUM($E$5:E9)-(1+Premissas!$B$17)*SUM($C$5:C9) -> -382.58091 | V9: =(G9+H9)*Premissas!$B$21 -> 0.13333333 | W9: =IF(V9>0,DATE(YEAR(B9),MONTH(B9)+1,Premissas!$B$16)-Premissas!$B$11+1-Premissas!$B$15,0) -> 36 | X9: =X8-Y8+C9*(1+Premissas!$B$17) -> 56.915 | Y9: =IF(OR(X9>=Premissas!$B$13,B9=DATE(YEAR(B9),MONTH(B9)+1,0)),X9,0) -> 0 | Z9: =Z8-AA8+C9/Premissas!$B$18*Premissas!$B$20 -> 18 | AA9: =IF(OR(Z9>=Premissas!$B$14,B9=DATE(YEAR(B9),MONTH(B9)+1,0)),Z9,0) -> 0 | AB9: =IF(AA9>0,IF(DAY(B9)<=Premissas!$B$12,DATE(YEAR(B9),MONTH(B9),Premissas!$B$16),DATE(YEAR(B9),MONTH(B9)+1,Premissas!$B$16))-Premissas!$B$11+1-Premissas!$B$15,0) -> 0
A10: 6 | B10: =Premissas!$B$11+A10-1 -> 46323 | C10: =IF(A10<=Premissas!$B$7,Premissas!$B$6/Premissas!$B$7,IF(A10<=Premissas!$B$7+Premissas!$B$8,0,IF(A10<=Premissas!$B$7+Premissas!$B$8+Premissas!$B$10,Premissas!$B$9/Premissas!$B$10,0))) -> 50 | D10: =IF(Y10>0,IF(DAY(B10)<=Premissas!$B$12,DATE(YEAR(B10),MONTH(B10),Premissas!$B$16),DATE(YEAR(B10),MONTH(B10)+1,Premissas!$B$16))-Premissas!$B$11+1-Premissas!$B$15,0) -> 36 | E10: =-SUMIF($D$5:$D$94,A10,$Y$5:$Y$94) -> 0 | F10: =-SUMIF($W$5:$W$94,A10,$V$5:$V$94)-SUMIF($AB$5:$AB$94,A10,$AA$5:$AA$94) -> 0 | G10: =C10/Premissas!$B$18*Premissas!$B$19*Premissas!$B$23 -> 2.3333333 | H10: =C10/Premissas!$B$18*Premissas!$B$19*Premissas!$B$24 -> 1 | I10: =-IF($A10-(Premissas!$B$60)>=1,INDEX($G$5:$G$94,$A10-(Premissas!$B$60)),0)*(Premissas!$B$59*Unitário!$B$22+(Premissas!$B$61*Unitário!$B$24+Premissas!$B$63*Unitário!$B$25)) -> -146.33782 | J10: =IF($A10-(Premissas!$B$54)>=1,INDEX($G$5:$G$94,$A10-(Premissas!$B$54)),0)*Premissas!$B$26*((Premissas!$B$59*Unitário!$B$22+(Premissas!$B$61*Unitário!$B$24+Premissas!$B$63*Unitário!$B$25))-Premissas!$B$39) -> 20.91473 | K10: =IF($A10-(Premissas!$B$54+Premissas!$B$57)>=1,INDEX($G$5:$G$94,$A10-(Premissas!$B$54+Premissas!$B$57)),0)*(1-Premissas!$B$26)*Premissas!$B$27*(Premissas!$B$59*Unitário!$B$22+(1-Premissas!$B$62)*(Premissas!$B$61*Unitário!$B$24+Premissas!$B$63*Unitário!$B$25)-Premissas!$B$62*((1-Premissas!$B$61)*Unitário!$B$24+(1-Premissas!$B$63)*Unitário!$B$25)-Premissas!$B$40) -> 0 | L10: =IF($A10-(Premissas!$B$54+Premissas!$B$55)>=1,INDEX($G$5:$G$94,$A10-(Premissas!$B$54+Premissas!$B$55)),0)*Unitário!$B$21*(Premissas!$B$51-(1-Premissas!$B$61)*Unitário!$B$24-(1-Premissas!$B$63)*Unitário!$B$25-(1-Premissas!$B$59)*Unitário!$B$22) -> 0 | M10: =IF($A10-(Premissas!$B$56)>=1,INDEX($H$5:$H$94,$A10-(Premissas!$B$56)),0)*(Premissas!$B$52-Unitário!$B$27) -> 112.92024 | N10: =-IF($A10-(Premissas!$B$60)>=1,INDEX($H$5:$H$94,$A10-(Premissas!$B$60)),0)*(Premissas!$B$59*Unitário!$B$22+Premissas!$B$31) -> -35 | O10: =IF($A10-(Premissas!$B$54+Premissas!$B$57)>=1,INDEX($H$5:$H$94,$A10-(Premissas!$B$54+Premissas!$B$57)),0)*Premissas!$B$27*(-Premissas!$B$52-Premissas!$B$41+Unitário!$B$27+(1-Premissas!$B$62)*Premissas!$B$31+Premissas!$B$59*Unitário!$B$22) -> 0 | P10: =-Premissas!$B$42*(IF($A10-(Premissas!$B$54+Premissas!$B$55)>=1,INDEX($G$5:$G$94,$A10-(Premissas!$B$54+Premissas!$B$55)),0)*Unitário!$B$21*Premissas!$B$51+IF($A10-(Premissas!$B$56)>=1,INDEX($H$5:$H$94,$A10-(Premissas!$B$56)),0)*(1-Premissas!$B$27)*Premissas!$B$52) -> 0 | Q10: =-IF(AND(DAY(B10+Premissas!$B$15)=Premissas!$B$16,B10+Premissas!$B$15>=DATE(YEAR(Premissas!$B$11),MONTH(Premissas!$B$11)+1,Premissas!$B$16)),Premissas!$B$43,0)-IF(OR(E10<0,F10<0,IF(AND(DAY(B10+Premissas!$B$15)=Premissas!$B$16,B10+Premissas!$B$15>=DATE(YEAR(Premissas!$B$11),MONTH(Premissas!$B$11)+1,Premissas!$B$16)),Premissas!$B$43,0)>0),Premissas!$B$67*Premissas!$B$68,0) -> 0 | R10: =E10+F10+SUM(I10:Q10) -> -47.502855 | S10: =S9+R10 -> -145.50877 | T10: =IF(AND($A10>$B$100,S10>=0),1,0) -> 0 | U10: =S10-SUM($E$5:E10)-(1+Premissas!$B$17)*SUM($C$5:C10) -> -486.99877 | V10: =(G10+H10)*Premissas!$B$21 -> 0.13333333 | W10: =IF(V10>0,DATE(YEAR(B10),MONTH(B10)+1,Premissas!$B$16)-Premissas!$B$11+1-Premissas!$B$15,0) -> 36 | X10: =X9-Y9+C10*(1+Premissas!$B$17) -> 113.83 | Y10: =IF(OR(X10>=Premissas!$B$13,B10=DATE(YEAR(B10),MONTH(B10)+1,0)),X10,0) -> 113.83 | Z10: =Z9-AA9+C10/Premissas!$B$18*Premissas!$B$20 -> 27 | AA10: =IF(OR(Z10>=Premissas!$B$14,B10=DATE(YEAR(B10),MONTH(B10)+1,0)),Z10,0) -> 27 | AB10: =IF(AA10>0,IF(DAY(B10)<=Premissas!$B$12,DATE(YEAR(B10),MONTH(B10),Premissas!$B$16),DATE(YEAR(B10),MONTH(B10)+1,Premissas!$B$16))-Premissas!$B$11+1-Premissas!$B$15,0) -> 36
A11: 7 | B11: =Premissas!$B$11+A11-1 -> 46324 | C11: =IF(A11<=Premissas!$B$7,Premissas!$B$6/Premissas!$B$7,IF(A11<=Premissas!$B$7+Premissas!$B$8,0,IF(A11<=Premissas!$B$7+Premissas!$B$8+Premissas!$B$10,Premissas!$B$9/Premissas!$B$10,0))) -> 50 | D11: =IF(Y11>0,IF(DAY(B11)<=Premissas!$B$12,DATE(YEAR(B11),MONTH(B11),Premissas!$B$16),DATE(YEAR(B11),MONTH(B11)+1,Premissas!$B$16))-Premissas!$B$11+1-Premissas!$B$15,0) -> 0 | E11: =-SUMIF($D$5:$D$94,A11,$Y$5:$Y$94) -> 0 | F11: =-SUMIF($W$5:$W$94,A11,$V$5:$V$94)-SUMIF($AB$5:$AB$94,A11,$AA$5:$AA$94) -> 0 | G11: =C11/Premissas!$B$18*Premissas!$B$19*Premissas!$B$23 -> 2.3333333 | H11: =C11/Premissas!$B$18*Premissas!$B$19*Premissas!$B$24 -> 1 | I11: =-IF($A11-(Premissas!$B$60)>=1,INDEX($G$5:$G$94,$A11-(Premissas!$B$60)),0)*(Premissas!$B$59*Unitário!$B$22+(Premissas!$B$61*Unitário!$B$24+Premissas!$B$63*Unitário!$B$25)) -> -146.33782 | J11: =IF($A11-(Premissas!$B$54)>=1,INDEX($G$5:$G$94,$A11-(Premissas!$B$54)),0)*Premissas!$B$26*((Premissas!$B$59*Unitário!$B$22+(Premissas!$B$61*Unitário!$B$24+Premissas!$B$63*Unitário!$B$25))-Premissas!$B$39) -> 20.91473 | K11: =IF($A11-(Premissas!$B$54+Premissas!$B$57)>=1,INDEX($G$5:$G$94,$A11-(Premissas!$B$54+Premissas!$B$57)),0)*(1-Premissas!$B$26)*Premissas!$B$27*(Premissas!$B$59*Unitário!$B$22+(1-Premissas!$B$62)*(Premissas!$B$61*Unitário!$B$24+Premissas!$B$63*Unitário!$B$25)-Premissas!$B$62*((1-Premissas!$B$61)*Unitário!$B$24+(1-Premissas!$B$63)*Unitário!$B$25)-Premissas!$B$40) -> 0 | L11: =IF($A11-(Premissas!$B$54+Premissas!$B$55)>=1,INDEX($G$5:$G$94,$A11-(Premissas!$B$54+Premissas!$B$55)),0)*Unitário!$B$21*(Premissas!$B$51-(1-Premissas!$B$61)*Unitário!$B$24-(1-Premissas!$B$63)*Unitário!$B$25-(1-Premissas!$B$59)*Unitário!$B$22) -> 0 | M11: =IF($A11-(Premissas!$B$56)>=1,INDEX($H$5:$H$94,$A11-(Premissas!$B$56)),0)*(Premissas!$B$52-Unitário!$B$27) -> 112.92024 | N11: =-IF($A11-(Premissas!$B$60)>=1,INDEX($H$5:$H$94,$A11-(Premissas!$B$60)),0)*(Premissas!$B$59*Unitário!$B$22+Premissas!$B$31) -> -35 | O11: =IF($A11-(Premissas!$B$54+Premissas!$B$57)>=1,INDEX($H$5:$H$94,$A11-(Premissas!$B$54+Premissas!$B$57)),0)*Premissas!$B$27*(-Premissas!$B$52-Premissas!$B$41+Unitário!$B$27+(1-Premissas!$B$62)*Premissas!$B$31+Premissas!$B$59*Unitário!$B$22) -> 0 | P11: =-Premissas!$B$42*(IF($A11-(Premissas!$B$54+Premissas!$B$55)>=1,INDEX($G$5:$G$94,$A11-(Premissas!$B$54+Premissas!$B$55)),0)*Unitário!$B$21*Premissas!$B$51+IF($A11-(Premissas!$B$56)>=1,INDEX($H$5:$H$94,$A11-(Premissas!$B$56)),0)*(1-Premissas!$B$27)*Premissas!$B$52) -> 0 | Q11: =-IF(AND(DAY(B11+Premissas!$B$15)=Premissas!$B$16,B11+Premissas!$B$15>=DATE(YEAR(Premissas!$B$11),MONTH(Premissas!$B$11)+1,Premissas!$B$16)),Premissas!$B$43,0)-IF(OR(E11<0,F11<0,IF(AND(DAY(B11+Premissas!$B$15)=Premissas!$B$16,B11+Premissas!$B$15>=DATE(YEAR(Premissas!$B$11),MONTH(Premissas!$B$11)+1,Premissas!$B$16)),Premissas!$B$43,0)>0),Premissas!$B$67*Premissas!$B$68,0) -> 0 | R11: =E11+F11+SUM(I11:Q11) -> -47.502855 | S11: =S10+R11 -> -193.01162 | T11: =IF(AND($A11>$B$100,S11>=0),1,0) -> 0 | U11: =S11-SUM($E$5:E11)-(1+Premissas!$B$17)*SUM($C$5:C11) -> -591.41662 | V11: =(G11+H11)*Premissas!$B$21 -> 0.13333333 | W11: =IF(V11>0,DATE(YEAR(B11),MONTH(B11)+1,Premissas!$B$16)-Premissas!$B$11+1-Premissas!$B$15,0) -> 36 | X11: =X10-Y10+C11*(1+Premissas!$B$17) -> 56.915 | Y11: =IF(OR(X11>=Premissas!$B$13,B11=DATE(YEAR(B11),MONTH(B11)+1,0)),X11,0) -> 0 | Z11: =Z10-AA10+C11/Premissas!$B$18*Premissas!$B$20 -> 9 | AA11: =IF(OR(Z11>=Premissas!$B$14,B11=DATE(YEAR(B11),MONTH(B11)+1,0)),Z11,0) -> 0 | AB11: =IF(AA11>0,IF(DAY(B11)<=Premissas!$B$12,DATE(YEAR(B11),MONTH(B11),Premissas!$B$16),DATE(YEAR(B11),MONTH(B11)+1,Premissas!$B$16))-Premissas!$B$11+1-Premissas!$B$15,0) -> 0
A12: 8 | B12: =Premissas!$B$11+A12-1 -> 46325 | C12: =IF(A12<=Premissas!$B$7,Premissas!$B$6/Premissas!$B$7,IF(A12<=Premissas!$B$7+Premissas!$B$8,0,IF(A12<=Premissas!$B$7+Premissas!$B$8+Premissas!$B$10,Premissas!$B$9/Premissas!$B$10,0))) -> 0 | D12: =IF(Y12>0,IF(DAY(B12)<=Premissas!$B$12,DATE(YEAR(B12),MONTH(B12),Premissas!$B$16),DATE(YEAR(B12),MONTH(B12)+1,Premissas!$B$16))-Premissas!$B$11+1-Premissas!$B$15,0) -> 0 | E12: =-SUMIF($D$5:$D$94,A12,$Y$5:$Y$94) -> 0 | F12: =-SUMIF($W$5:$W$94,A12,$V$5:$V$94)-SUMIF($AB$5:$AB$94,A12,$AA$5:$AA$94) -> 0 | G12: =C12/Premissas!$B$18*Premissas!$B$19*Premissas!$B$23 -> 0 | H12: =C12/Premissas!$B$18*Premissas!$B$19*Premissas!$B$24 -> 0 | I12: =-IF($A12-(Premissas!$B$60)>=1,INDEX($G$5:$G$94,$A12-(Premissas!$B$60)),0)*(Premissas!$B$59*Unitário!$B$22+(Premissas!$B$61*Unitário!$B$24+Premissas!$B$63*Unitário!$B$25)) -> -146.33782 | J12: =IF($A12-(Premissas!$B$54)>=1,INDEX($G$5:$G$94,$A12-(Premissas!$B$54)),0)*Premissas!$B$26*((Premissas!$B$59*Unitário!$B$22+(Premissas!$B$61*Unitário!$B$24+Premissas!$B$63*Unitário!$B$25))-Premissas!$B$39) -> 20.91473 | K12: =IF($A12-(Premissas!$B$54+Premissas!$B$57)>=1,INDEX($G$5:$G$94,$A12-(Premissas!$B$54+Premissas!$B$57)),0)*(1-Premissas!$B$26)*Premissas!$B$27*(Premissas!$B$59*Unitário!$B$22+(1-Premissas!$B$62)*(Premissas!$B$61*Unitário!$B$24+Premissas!$B$63*Unitário!$B$25)-Premissas!$B$62*((1-Premissas!$B$61)*Unitário!$B$24+(1-Premissas!$B$63)*Unitário!$B$25)-Premissas!$B$40) -> 0 | L12: =IF($A12-(Premissas!$B$54+Premissas!$B$55)>=1,INDEX($G$5:$G$94,$A12-(Premissas!$B$54+Premissas!$B$55)),0)*Unitário!$B$21*(Premissas!$B$51-(1-Premissas!$B$61)*Unitário!$B$24-(1-Premissas!$B$63)*Unitário!$B$25-(1-Premissas!$B$59)*Unitário!$B$22) -> 0 | M12: =IF($A12-(Premissas!$B$56)>=1,INDEX($H$5:$H$94,$A12-(Premissas!$B$56)),0)*(Premissas!$B$52-Unitário!$B$27) -> 0 | N12: =-IF($A12-(Premissas!$B$60)>=1,INDEX($H$5:$H$94,$A12-(Premissas!$B$60)),0)*(Premissas!$B$59*Unitário!$B$22+Premissas!$B$31) -> -35 | O12: =IF($A12-(Premissas!$B$54+Premissas!$B$57)>=1,INDEX($H$5:$H$94,$A12-(Premissas!$B$54+Premissas!$B$57)),0)*Premissas!$B$27*(-Premissas!$B$52-Premissas!$B$41+Unitário!$B$27+(1-Premissas!$B$62)*Premissas!$B$31+Premissas!$B$59*Unitário!$B$22) -> 0 | P12: =-Premissas!$B$42*(IF($A12-(Premissas!$B$54+Premissas!$B$55)>=1,INDEX($G$5:$G$94,$A12-(Premissas!$B$54+Premissas!$B$55)),0)*Unitário!$B$21*Premissas!$B$51+IF($A12-(Premissas!$B$56)>=1,INDEX($H$5:$H$94,$A12-(Premissas!$B$56)),0)*(1-Premissas!$B$27)*Premissas!$B$52) -> 0 | Q12: =-IF(AND(DAY(B12+Premissas!$B$15)=Premissas!$B$16,B12+Premissas!$B$15>=DATE(YEAR(Premissas!$B$11),MONTH(Premissas!$B$11)+1,Premissas!$B$16)),Premissas!$B$43,0)-IF(OR(E12<0,F12<0,IF(AND(DAY(B12+Premissas!$B$15)=Premissas!$B$16,B12+Premissas!$B$15>=DATE(YEAR(Premissas!$B$11),MONTH(Premissas!$B$11)+1,Premissas!$B$16)),Premissas!$B$43,0)>0),Premissas!$B$67*Premissas!$B$68,0) -> 0 | R12: =E12+F12+SUM(I12:Q12) -> -160.42309 | S12: =S11+R12 -> -353.43471 | T12: =IF(AND($A12>$B$100,S12>=0),1,0) -> 0 | U12: =S12-SUM($E$5:E12)-(1+Premissas!$B$17)*SUM($C$5:C12) -> -751.83971 | V12: =(G12+H12)*Premissas!$B$21 -> 0 | W12: =IF(V12>0,DATE(YEAR(B12),MONTH(B12)+1,Premissas!$B$16)-Premissas!$B$11+1-Premissas!$B$15,0) -> 0 | X12: =X11-Y11+C12*(1+Premissas!$B$17) -> 56.915 | Y12: =IF(OR(X12>=Premissas!$B$13,B12=DATE(YEAR(B12),MONTH(B12)+1,0)),X12,0) -> 0 | Z12: =Z11-AA11+C12/Premissas!$B$18*Premissas!$B$20 -> 9 | AA12: =IF(OR(Z12>=Premissas!$B$14,B12=DATE(YEAR(B12),MONTH(B12)+1,0)),Z12,0) -> 0 | AB12: =IF(AA12>0,IF(DAY(B12)<=Premissas!$B$12,DATE(YEAR(B12),MONTH(B12),Premissas!$B$16),DATE(YEAR(B12),MONTH(B12)+1,Premissas!$B$16))-Premissas!$B$11+1-Premissas!$B$15,0) -> 0
A13: 9 | B13: =Premissas!$B$11+A13-1 -> 46326 | C13: =IF(A13<=Premissas!$B$7,Premissas!$B$6/Premissas!$B$7,IF(A13<=Premissas!$B$7+Premissas!$B$8,0,IF(A13<=Premissas!$B$7+Premissas!$B$8+Premissas!$B$10,Premissas!$B$9/Premissas!$B$10,0))) -> 0 | D13: =IF(Y13>0,IF(DAY(B13)<=Premissas!$B$12,DATE(YEAR(B13),MONTH(B13),Premissas!$B$16),DATE(YEAR(B13),MONTH(B13)+1,Premissas!$B$16))-Premissas!$B$11+1-Premissas!$B$15,0) -> 36 | E13: =-SUMIF($D$5:$D$94,A13,$Y$5:$Y$94) -> 0 | F13: =-SUMIF($W$5:$W$94,A13,$V$5:$V$94)-SUMIF($AB$5:$AB$94,A13,$AA$5:$AA$94) -> 0 | G13: =C13/Premissas!$B$18*Premissas!$B$19*Premissas!$B$23 -> 0 | H13: =C13/Premissas!$B$18*Premissas!$B$19*Premissas!$B$24 -> 0 | I13: =-IF($A13-(Premissas!$B$60)>=1,INDEX($G$5:$G$94,$A13-(Premissas!$B$60)),0)*(Premissas!$B$59*Unitário!$B$22+(Premissas!$B$61*Unitário!$B$24+Premissas!$B$63*Unitário!$B$25)) -> 0 | J13: =IF($A13-(Premissas!$B$54)>=1,INDEX($G$5:$G$94,$A13-(Premissas!$B$54)),0)*Premissas!$B$26*((Premissas!$B$59*Unitário!$B$22+(Premissas!$B$61*Unitário!$B$24+Premissas!$B$63*Unitário!$B$25))-Premissas!$B$39) -> 20.91473 | K13: =IF($A13-(Premissas!$B$54+Premissas!$B$57)>=1,INDEX($G$5:$G$94,$A13-(Premissas!$B$54+Premissas!$B$57)),0)*(1-Premissas!$B$26)*Premissas!$B$27*(Premissas!$B$59*Unitário!$B$22+(1-Premissas!$B$62)*(Premissas!$B$61*Unitário!$B$24+Premissas!$B$63*Unitário!$B$25)-Premissas!$B$62*((1-Premissas!$B$61)*Unitário!$B$24+(1-Premissas!$B$63)*Unitário!$B$25)-Premissas!$B$40) -> 0 | L13: =IF($A13-(Premissas!$B$54+Premissas!$B$55)>=1,INDEX($G$5:$G$94,$A13-(Premissas!$B$54+Premissas!$B$55)),0)*Unitário!$B$21*(Premissas!$B$51-(1-Premissas!$B$61)*Unitário!$B$24-(1-Premissas!$B$63)*Unitário!$B$25-(1-Premissas!$B$59)*Unitário!$B$22) -> 0 | M13: =IF($A13-(Premissas!$B$56)>=1,INDEX($H$5:$H$94,$A13-(Premissas!$B$56)),0)*(Premissas!$B$52-Unitário!$B$27) -> 0 | N13: =-IF($A13-(Premissas!$B$60)>=1,INDEX($H$5:$H$94,$A13-(Premissas!$B$60)),0)*(Premissas!$B$59*Unitário!$B$22+Premissas!$B$31) -> 0 | O13: =IF($A13-(Premissas!$B$54+Premissas!$B$57)>=1,INDEX($H$5:$H$94,$A13-(Premissas!$B$54+Premissas!$B$57)),0)*Premissas!$B$27*(-Premissas!$B$52-Premissas!$B$41+Unitário!$B$27+(1-Premissas!$B$62)*Premissas!$B$31+Premissas!$B$59*Unitário!$B$22) -> 0 | P13: =-Premissas!$B$42*(IF($A13-(Premissas!$B$54+Premissas!$B$55)>=1,INDEX($G$5:$G$94,$A13-(Premissas!$B$54+Premissas!$B$55)),0)*Unitário!$B$21*Premissas!$B$51+IF($A13-(Premissas!$B$56)>=1,INDEX($H$5:$H$94,$A13-(Premissas!$B$56)),0)*(1-Premissas!$B$27)*Premissas!$B$52) -> 0 | Q13: =-IF(AND(DAY(B13+Premissas!$B$15)=Premissas!$B$16,B13+Premissas!$B$15>=DATE(YEAR(Premissas!$B$11),MONTH(Premissas!$B$11)+1,Premissas!$B$16)),Premissas!$B$43,0)-IF(OR(E13<0,F13<0,IF(AND(DAY(B13+Premissas!$B$15)=Premissas!$B$16,B13+Premissas!$B$15>=DATE(YEAR(Premissas!$B$11),MONTH(Premissas!$B$11)+1,Premissas!$B$16)),Premissas!$B$43,0)>0),Premissas!$B$67*Premissas!$B$68,0) -> 0 | R13: =E13+F13+SUM(I13:Q13) -> 20.91473 | S13: =S12+R13 -> -332.51998 | T13: =IF(AND($A13>$B$100,S13>=0),1,0) -> 0 | U13: =S13-SUM($E$5:E13)-(1+Premissas!$B$17)*SUM($C$5:C13) -> -730.92498 | V13: =(G13+H13)*Premissas!$B$21 -> 0 | W13: =IF(V13>0,DATE(YEAR(B13),MONTH(B13)+1,Premissas!$B$16)-Premissas!$B$11+1-Premissas!$B$15,0) -> 0 | X13: =X12-Y12+C13*(1+Premissas!$B$17) -> 56.915 | Y13: =IF(OR(X13>=Premissas!$B$13,B13=DATE(YEAR(B13),MONTH(B13)+1,0)),X13,0) -> 56.915 | Z13: =Z12-AA12+C13/Premissas!$B$18*Premissas!$B$20 -> 9 | AA13: =IF(OR(Z13>=Premissas!$B$14,B13=DATE(YEAR(B13),MONTH(B13)+1,0)),Z13,0) -> 9 | AB13: =IF(AA13>0,IF(DAY(B13)<=Premissas!$B$12,DATE(YEAR(B13),MONTH(B13),Premissas!$B$16),DATE(YEAR(B13),MONTH(B13)+1,Premissas!$B$16))-Premissas!$B$11+1-Premissas!$B$15,0) -> 36
A14: 10 | B14: =Premissas!$B$11+A14-1 -> 46327 | C14: =IF(A14<=Premissas!$B$7,Premissas!$B$6/Premissas!$B$7,IF(A14<=Premissas!$B$7+Premissas!$B$8,0,IF(A14<=Premissas!$B$7+Premissas!$B$8+Premissas!$B$10,Premissas!$B$9/Premissas!$B$10,0))) -> 50 | D14: =IF(Y14>0,IF(DAY(B14)<=Premissas!$B$12,DATE(YEAR(B14),MONTH(B14),Premissas!$B$16),DATE(YEAR(B14),MONTH(B14)+1,Premissas!$B$16))-Premissas!$B$11+1-Premissas!$B$15,0) -> 0 | E14: =-SUMIF($D$5:$D$94,A14,$Y$5:$Y$94) -> 0 | F14: =-SUMIF($W$5:$W$94,A14,$V$5:$V$94)-SUMIF($AB$5:$AB$94,A14,$AA$5:$AA$94) -> 0 | G14: =C14/Premissas!$B$18*Premissas!$B$19*Premissas!$B$23 -> 2.3333333 | H14: =C14/Premissas!$B$18*Premissas!$B$19*Premissas!$B$24 -> 1 | I14: =-IF($A14-(Premissas!$B$60)>=1,INDEX($G$5:$G$94,$A14-(Premissas!$B$60)),0)*(Premissas!$B$59*Unitário!$B$22+(Premissas!$B$61*Unitário!$B$24+Premissas!$B$63*Unitário!$B$25)) -> 0 | J14: =IF($A14-(Premissas!$B$54)>=1,INDEX($G$5:$G$94,$A14-(Premissas!$B$54)),0)*Premissas!$B$26*((Premissas!$B$59*Unitário!$B$22+(Premissas!$B$61*Unitário!$B$24+Premissas!$B$63*Unitário!$B$25))-Premissas!$B$39) -> 0 | K14: =IF($A14-(Premissas!$B$54+Premissas!$B$57)>=1,INDEX($G$5:$G$94,$A14-(Premissas!$B$54+Premissas!$B$57)),0)*(1-Premissas!$B$26)*Premissas!$B$27*(Premissas!$B$59*Unitário!$B$22+(1-Premissas!$B$62)*(Premissas!$B$61*Unitário!$B$24+Premissas!$B$63*Unitário!$B$25)-Premissas!$B$62*((1-Premissas!$B$61)*Unitário!$B$24+(1-Premissas!$B$63)*Unitário!$B$25)-Premissas!$B$40) -> 6.3360391 | L14: =IF($A14-(Premissas!$B$54+Premissas!$B$55)>=1,INDEX($G$5:$G$94,$A14-(Premissas!$B$54+Premissas!$B$55)),0)*Unitário!$B$21*(Premissas!$B$51-(1-Premissas!$B$61)*Unitário!$B$24-(1-Premissas!$B$63)*Unitário!$B$25-(1-Premissas!$B$59)*Unitário!$B$22) -> 0 | M14: =IF($A14-(Premissas!$B$56)>=1,INDEX($H$5:$H$94,$A14-(Premissas!$B$56)),0)*(Premissas!$B$52-Unitário!$B$27) -> 112.92024 | N14: =-IF($A14-(Premissas!$B$60)>=1,INDEX($H$5:$H$94,$A14-(Premissas!$B$60)),0)*(Premissas!$B$59*Unitário!$B$22+Premissas!$B$31) -> 0 | O14: =IF($A14-(Premissas!$B$54+Premissas!$B$57)>=1,INDEX($H$5:$H$94,$A14-(Premissas!$B$54+Premissas!$B$57)),0)*Premissas!$B$27*(-Premissas!$B$52-Premissas!$B$41+Unitário!$B$27+(1-Premissas!$B$62)*Premissas!$B$31+Premissas!$B$59*Unitário!$B$22) -> -12.792024 | P14: =-Premissas!$B$42*(IF($A14-(Premissas!$B$54+Premissas!$B$55)>=1,INDEX($G$5:$G$94,$A14-(Premissas!$B$54+Premissas!$B$55)),0)*Unitário!$B$21*Premissas!$B$51+IF($A14-(Premissas!$B$56)>=1,INDEX($H$5:$H$94,$A14-(Premissas!$B$56)),0)*(1-Premissas!$B$27)*Premissas!$B$52) -> 0 | Q14: =-IF(AND(DAY(B14+Premissas!$B$15)=Premissas!$B$16,B14+Premissas!$B$15>=DATE(YEAR(Premissas!$B$11),MONTH(Premissas!$B$11)+1,Premissas!$B$16)),Premissas!$B$43,0)-IF(OR(E14<0,F14<0,IF(AND(DAY(B14+Premissas!$B$15)=Premissas!$B$16,B14+Premissas!$B$15>=DATE(YEAR(Premissas!$B$11),MONTH(Premissas!$B$11)+1,Premissas!$B$16)),Premissas!$B$43,0)>0),Premissas!$B$67*Premissas!$B$68,0) -> 0 | R14: =E14+F14+SUM(I14:Q14) -> 106.46425 | S14: =S13+R14 -> -226.05573 | T14: =IF(AND($A14>$B$100,S14>=0),1,0) -> 0 | U14: =S14-SUM($E$5:E14)-(1+Premissas!$B$17)*SUM($C$5:C14) -> -681.37573 | V14: =(G14+H14)*Premissas!$B$21 -> 0.13333333 | W14: =IF(V14>0,DATE(YEAR(B14),MONTH(B14)+1,Premissas!$B$16)-Premissas!$B$11+1-Premissas!$B$15,0) -> 66 | X14: =X13-Y13+C14*(1+Premissas!$B$17) -> 56.915 | Y14: =IF(OR(X14>=Premissas!$B$13,B14=DATE(YEAR(B14),MONTH(B14)+1,0)),X14,0) -> 0 | Z14: =Z13-AA13+C14/Premissas!$B$18*Premissas!$B$20 -> 9 | AA14: =IF(OR(Z14>=Premissas!$B$14,B14=DATE(YEAR(B14),MONTH(B14)+1,0)),Z14,0) -> 0 | AB14: =IF(AA14>0,IF(DAY(B14)<=Premissas!$B$12,DATE(YEAR(B14),MONTH(B14),Premissas!$B$16),DATE(YEAR(B14),MONTH(B14)+1,Premissas!$B$16))-Premissas!$B$11+1-Premissas!$B$15,0) -> 0
A15: 11 | B15: =Premissas!$B$11+A15-1 -> 46328 | C15: =IF(A15<=Premissas!$B$7,Premissas!$B$6/Premissas!$B$7,IF(A15<=Premissas!$B$7+Premissas!$B$8,0,IF(A15<=Premissas!$B$7+Premissas!$B$8+Premissas!$B$10,Premissas!$B$9/Premissas!$B$10,0))) -> 50 | D15: =IF(Y15>0,IF(DAY(B15)<=Premissas!$B$12,DATE(YEAR(B15),MONTH(B15),Premissas!$B$16),DATE(YEAR(B15),MONTH(B15)+1,Premissas!$B$16))-Premissas!$B$11+1-Premissas!$B$15,0) -> 36 | E15: =-SUMIF($D$5:$D$94,A15,$Y$5:$Y$94) -> 0 | F15: =-SUMIF($W$5:$W$94,A15,$V$5:$V$94)-SUMIF($AB$5:$AB$94,A15,$AA$5:$AA$94) -> 0 | G15: =C15/Premissas!$B$18*Premissas!$B$19*Premissas!$B$23 -> 2.3333333 | H15: =C15/Premissas!$B$18*Premissas!$B$19*Premissas!$B$24 -> 1 | I15: =-IF($A15-(Premissas!$B$60)>=1,INDEX($G$5:$G$94,$A15-(Premissas!$B$60)),0)*(Premissas!$B$59*Unitário!$B$22+(Premissas!$B$61*Unitário!$B$24+Premissas!$B$63*Unitário!$B$25)) -> -146.33782 | J15: =IF($A15-(Premissas!$B$54)>=1,INDEX($G$5:$G$94,$A15-(Premissas!$B$54)),0)*Premissas!$B$26*((Premissas!$B$59*Unitário!$B$22+(Premissas!$B$61*Unitário!$B$24+Premissas!$B$63*Unitário!$B$25))-Premissas!$B$39) -> 0 | K15: =IF($A15-(Premissas!$B$54+Premissas!$B$57)>=1,INDEX($G$5:$G$94,$A15-(Premissas!$B$54+Premissas!$B$57)),0)*(1-Premissas!$B$26)*Premissas!$B$27*(Premissas!$B$59*Unitário!$B$22+(1-Premissas!$B$62)*(Premissas!$B$61*Unitário!$B$24+Premissas!$B$63*Unitário!$B$25)-Premissas!$B$62*((1-Premissas!$B$61)*Unitário!$B$24+(1-Premissas!$B$63)*Unitário!$B$25)-Premissas!$B$40) -> 6.3360391 | L15: =IF($A15-(Premissas!$B$54+Premissas!$B$55)>=1,INDEX($G$5:$G$94,$A15-(Premissas!$B$54+Premissas!$B$55)),0)*Unitário!$B$21*(Premissas!$B$51-(1-Premissas!$B$61)*Unitário!$B$24-(1-Premissas!$B$63)*Unitário!$B$25-(1-Premissas!$B$59)*Unitário!$B$22) -> 0 | M15: =IF($A15-(Premissas!$B$56)>=1,INDEX($H$5:$H$94,$A15-(Premissas!$B$56)),0)*(Premissas!$B$52-Unitário!$B$27) -> 112.92024 | N15: =-IF($A15-(Premissas!$B$60)>=1,INDEX($H$5:$H$94,$A15-(Premissas!$B$60)),0)*(Premissas!$B$59*Unitário!$B$22+Premissas!$B$31) -> -35 | O15: =IF($A15-(Premissas!$B$54+Premissas!$B$57)>=1,INDEX($H$5:$H$94,$A15-(Premissas!$B$54+Premissas!$B$57)),0)*Premissas!$B$27*(-Premissas!$B$52-Premissas!$B$41+Unitário!$B$27+(1-Premissas!$B$62)*Premissas!$B$31+Premissas!$B$59*Unitário!$B$22) -> -12.792024 | P15: =-Premissas!$B$42*(IF($A15-(Premissas!$B$54+Premissas!$B$55)>=1,INDEX($G$5:$G$94,$A15-(Premissas!$B$54+Premissas!$B$55)),0)*Unitário!$B$21*Premissas!$B$51+IF($A15-(Premissas!$B$56)>=1,INDEX($H$5:$H$94,$A15-(Premissas!$B$56)),0)*(1-Premissas!$B$27)*Premissas!$B$52) -> 0 | Q15: =-IF(AND(DAY(B15+Premissas!$B$15)=Premissas!$B$16,B15+Premissas!$B$15>=DATE(YEAR(Premissas!$B$11),MONTH(Premissas!$B$11)+1,Premissas!$B$16)),Premissas!$B$43,0)-IF(OR(E15<0,F15<0,IF(AND(DAY(B15+Premissas!$B$15)=Premissas!$B$16,B15+Premissas!$B$15>=DATE(YEAR(Premissas!$B$11),MONTH(Premissas!$B$11)+1,Premissas!$B$16)),Premissas!$B$43,0)>0),Premissas!$B$67*Premissas!$B$68,0) -> 0 | R15: =E15+F15+SUM(I15:Q15) -> -74.873569 | S15: =S14+R15 -> -300.9293 | T15: =IF(AND($A15>$B$100,S15>=0),1,0) -> 0 | U15: =S15-SUM($E$5:E15)-(1+Premissas!$B$17)*SUM($C$5:C15) -> -813.1643 | V15: =(G15+H15)*Premissas!$B$21 -> 0.13333333 | W15: =IF(V15>0,DATE(YEAR(B15),MONTH(B15)+1,Premissas!$B$16)-Premissas!$B$11+1-Premissas!$B$15,0) -> 66 | X15: =X14-Y14+C15*(1+Premissas!$B$17) -> 113.83 | Y15: =IF(OR(X15>=Premissas!$B$13,B15=DATE(YEAR(B15),MONTH(B15)+1,0)),X15,0) -> 113.83 | Z15: =Z14-AA14+C15/Premissas!$B$18*Premissas!$B$20 -> 18 | AA15: =IF(OR(Z15>=Premissas!$B$14,B15=DATE(YEAR(B15),MONTH(B15)+1,0)),Z15,0) -> 0 | AB15: =IF(AA15>0,IF(DAY(B15)<=Premissas!$B$12,DATE(YEAR(B15),MONTH(B15),Premissas!$B$16),DATE(YEAR(B15),MONTH(B15)+1,Premissas!$B$16))-Premissas!$B$11+1-Premissas!$B$15,0) -> 0
A16: 12 | B16: =Premissas!$B$11+A16-1 -> 46329 | C16: =IF(A16<=Premissas!$B$7,Premissas!$B$6/Premissas!$B$7,IF(A16<=Premissas!$B$7+Premissas!$B$8,0,IF(A16<=Premissas!$B$7+Premissas!$B$8+Premissas!$B$10,Premissas!$B$9/Premissas!$B$10,0))) -> 50 | D16: =IF(Y16>0,IF(DAY(B16)<=Premissas!$B$12,DATE(YEAR(B16),MONTH(B16),Premissas!$B$16),DATE(YEAR(B16),MONTH(B16)+1,Premissas!$B$16))-Premissas!$B$11+1-Premissas!$B$15,0) -> 0 | E16: =-SUMIF($D$5:$D$94,A16,$Y$5:$Y$94) -> 0 | F16: =-SUMIF($W$5:$W$94,A16,$V$5:$V$94)-SUMIF($AB$5:$AB$94,A16,$AA$5:$AA$94) -> 0 | G16: =C16/Premissas!$B$18*Premissas!$B$19*Premissas!$B$23 -> 2.3333333 | H16: =C16/Premissas!$B$18*Premissas!$B$19*Premissas!$B$24 -> 1 | I16: =-IF($A16-(Premissas!$B$60)>=1,INDEX($G$5:$G$94,$A16-(Premissas!$B$60)),0)*(Premissas!$B$59*Unitário!$B$22+(Premissas!$B$61*Unitário!$B$24+Premissas!$B$63*Unitário!$B$25)) -> -146.33782 | J16: =IF($A16-(Premissas!$B$54)>=1,INDEX($G$5:$G$94,$A16-(Premissas!$B$54)),0)*Premissas!$B$26*((Premissas!$B$59*Unitário!$B$22+(Premissas!$B$61*Unitário!$B$24+Premissas!$B$63*Unitário!$B$25))-Premissas!$B$39) -> 20.91473 | K16: =IF($A16-(Premissas!$B$54+Premissas!$B$57)>=1,INDEX($G$5:$G$94,$A16-(Premissas!$B$54+Premissas!$B$57)),0)*(1-Premissas!$B$26)*Premissas!$B$27*(Premissas!$B$59*Unitário!$B$22+(1-Premissas!$B$62)*(Premissas!$B$61*Unitário!$B$24+Premissas!$B$63*Unitário!$B$25)-Premissas!$B$62*((1-Premissas!$B$61)*Unitário!$B$24+(1-Premissas!$B$63)*Unitário!$B$25)-Premissas!$B$40) -> 6.3360391 | L16: =IF($A16-(Premissas!$B$54+Premissas!$B$55)>=1,INDEX($G$5:$G$94,$A16-(Premissas!$B$54+Premissas!$B$55)),0)*Unitário!$B$21*(Premissas!$B$51-(1-Premissas!$B$61)*Unitário!$B$24-(1-Premissas!$B$63)*Unitário!$B$25-(1-Premissas!$B$59)*Unitário!$B$22) -> 0 | M16: =IF($A16-(Premissas!$B$56)>=1,INDEX($H$5:$H$94,$A16-(Premissas!$B$56)),0)*(Premissas!$B$52-Unitário!$B$27) -> 112.92024 | N16: =-IF($A16-(Premissas!$B$60)>=1,INDEX($H$5:$H$94,$A16-(Premissas!$B$60)),0)*(Premissas!$B$59*Unitário!$B$22+Premissas!$B$31) -> -35 | O16: =IF($A16-(Premissas!$B$54+Premissas!$B$57)>=1,INDEX($H$5:$H$94,$A16-(Premissas!$B$54+Premissas!$B$57)),0)*Premissas!$B$27*(-Premissas!$B$52-Premissas!$B$41+Unitário!$B$27+(1-Premissas!$B$62)*Premissas!$B$31+Premissas!$B$59*Unitário!$B$22) -> -12.792024 | P16: =-Premissas!$B$42*(IF($A16-(Premissas!$B$54+Premissas!$B$55)>=1,INDEX($G$5:$G$94,$A16-(Premissas!$B$54+Premissas!$B$55)),0)*Unitário!$B$21*Premissas!$B$51+IF($A16-(Premissas!$B$56)>=1,INDEX($H$5:$H$94,$A16-(Premissas!$B$56)),0)*(1-Premissas!$B$27)*Premissas!$B$52) -> 0 | Q16: =-IF(AND(DAY(B16+Premissas!$B$15)=Premissas!$B$16,B16+Premissas!$B$15>=DATE(YEAR(Premissas!$B$11),MONTH(Premissas!$B$11)+1,Premissas!$B$16)),Premissas!$B$43,0)-IF(OR(E16<0,F16<0,IF(AND(DAY(B16+Premissas!$B$15)=Premissas!$B$16,B16+Premissas!$B$15>=DATE(YEAR(Premissas!$B$11),MONTH(Premissas!$B$11)+1,Premissas!$B$16)),Premissas!$B$43,0)>0),Premissas!$B$67*Premissas!$B$68,0) -> 0 | R16: =E16+F16+SUM(I16:Q16) -> -53.958839 | S16: =S15+R16 -> -354.88814 | T16: =IF(AND($A16>$B$100,S16>=0),1,0) -> 0 | U16: =S16-SUM($E$5:E16)-(1+Premissas!$B$17)*SUM($C$5:C16) -> -924.03814 | V16: =(G16+H16)*Premissas!$B$21 -> 0.13333333 | W16: =IF(V16>0,DATE(YEAR(B16),MONTH(B16)+1,Premissas!$B$16)-Premissas!$B$11+1-Premissas!$B$15,0) -> 66 | X16: =X15-Y15+C16*(1+Premissas!$B$17) -> 56.915 | Y16: =IF(OR(X16>=Premissas!$B$13,B16=DATE(YEAR(B16),MONTH(B16)+1,0)),X16,0) -> 0 | Z16: =Z15-AA15+C16/Premissas!$B$18*Premissas!$B$20 -> 27 | AA16: =IF(OR(Z16>=Premissas!$B$14,B16=DATE(YEAR(B16),MONTH(B16)+1,0)),Z16,0) -> 27 | AB16: =IF(AA16>0,IF(DAY(B16)<=Premissas!$B$12,DATE(YEAR(B16),MONTH(B16),Premissas!$B$16),DATE(YEAR(B16),MONTH(B16)+1,Premissas!$B$16))-Premissas!$B$11+1-Premissas!$B$15,0) -> 36
